<!--

MODEL: Univewrsal Robots UR5 + Robotiq S Model 3 Finger Gripper
AUTHOR: Andrea Franceschetti @IASLAB Research Group
UNIVERSITY: University of Padua
DEPARTMENT: Departement of Information Engineering DEI
Control Engineering / Automation Engineering

-->


<!--Link  MuJoCo modeling: http://www.mujoco.org/book/modeling.html-->

<mujoco model="ur5gripper">
    <compiler angle="radian"
              inertiafromgeom="true"
              texturedir="textures/"
              meshdir="mesh/visual/"/>
    <option timestep="2e-3"
            iterations="10"
            tolerance="1e-10"
            impratio="20"/>
    <size njmax="600" nconmax="150" nstack="300000"/>
    <!--<include file="plate-with-hole.xml"/>-->
    

    <default>
        <site rgba="0.8 0.6 0.7 0.3" type="ellipsoid" group="3"/>
        <geom contype='1' conaffinity='1' condim='4'  margin="1e-3" solref=".01 1" solimp=".99 .99 .01" />
        <joint armature="0.01" damping=".1"/>
        <default class="UR5">
            <joint damping='65'/>
        </default>
        <default class="UR5e">
            <joint damping='45'/>
        </default>
        <default class="GRIPPER">
            <joint damping='5'/>
        </default>
        <camera mode="fixed" pos="10 -2 2.7" axisangle="5 8 0 0.9"/>
    </default>

    <visual>
        <map fogstart="3" fogend="5" znear="0.05"/>
        <quality shadowsize="2048"/> 
        <scale framelength="0.1"
               framewidth="0.005"
               contactwidth="0.1"
               contactheight="0.005"
               forcewidth="0.01"
               />
	<global  fovy="45"  />
    </visual>

    <statistic center="0.9 -0.1 0.01"  />
 

    <!--Assets-->
    <asset>
        <!--Meshes-->
        <mesh name="base"           file="base.stl"     />
        <mesh name="shoulder"       file="shoulder.stl" />
        <mesh name="upperarm"       file="upperarm.stl" />
        <mesh name="forearm"        file="forearm.stl"  />
        <mesh name="wrist1"         file="wrist1.stl"   />
        <mesh name="wrist2"         file="wrist2.stl"   />
        <mesh name="wrist3"         file="wrist3.stl"   />
        <mesh name="gripperpalm"    file="palm.STL"     />
        <mesh name="link_0"         file="link_0.STL"   />
        <mesh name="link_1"         file="link_1.STL"   />
        <mesh name="link_2"         file="link_2.STL"   />
        <mesh name="link_3"         file="link_3.STL"   />
	<mesh name="BOX"      	    file="BOX.stl"      />
	<mesh file="AllFinal_hull_1.stl" name="1"  scale="1.2 1.2 0.8"/>
	<mesh file="AllFinal_hull_2.stl" name="2" scale="1.2 1.2 0.8" />
	<mesh file="AllFinal_hull_3.stl" name="3" scale="1.2 1.2 0.8" />
	<mesh file="AllFinal_hull_4.stl" name="4" scale="1.2 1.2 0.8" />
	<mesh file="AllFinal_hull_5.stl" name="5" scale="1.2 1.2 0.8 "/>
	<mesh file="AllFinal_hull_6.stl" name="6" scale="1.2 1.2 0.8" />
	<mesh file="AllFinal_hull_7.stl" name="7"  scale="1.2 1.2 0.8"/>
	<mesh file="AllFinal_hull_8.stl" name="8"  scale="1.2 1.2 0.8"/>
	<mesh file="AllFinal_hull_9.stl" name="9" scale="1.2 1.2 0.8" />
	<mesh file="AllFinal_hull_10.stl" name="10"  scale="1.2 1.2 0.8"/>
	<mesh file="AllFinal_hull_11.stl" name="11"  scale="1.2 1.2 0.8"/>
	<mesh file="AllFinal_hull_12.stl" name="12"  scale="1.2 1.2 0.8" />

    	

        <!--Textures-->
        <texture name="ur5_tex"     type="2d"       builtin="flat" height="32" width="32" rgb1="0.45 0.45 0.45" />
        <texture name="gripper_tex" type="2d"       builtin="flat" height="32" width="32" rgb1="0.45 0.45 0.45" rgb2="0 0 0"/>
        <texture name="bench_tex"   type="2d"       builtin="flat" height="32" width="32" rgb1="0.7 0.7 0.7" />
        <texture name="sky_tex"     type="skybox"   builtin="gradient" width="100" height="100" rgb1="1 1 1" rgb2="0.3 0.3 0.8" />
        <texture name="texgeom"     type="cube"     builtin="flat" mark="cross" width="127" height="1278" rgb1="0.8 0.6 0.4" rgb2="0.8 0.6 0.4" markrgb="1 1 1" random="0.01" />
        <texture name="floor_tex"   type="2d"        builtin="checker" rgb1=".2 .3 .4" rgb2=".1 .2 .3" width="100" height="100" />
        <texture name="wood"        type="cube"     file="wood2.png"/>
        <texture name="metal1"        type="cube"     file="metal2.png"/>
        <!--Materials-->
        <material name="ur5_mat"        texture="ur5_tex"   shininess="0.9" specular="0.75" reflectance="0.3"/>
        <material name="gripper_mat"    texture="gripper_tex"   shininess="0.9" specular="0.75" reflectance="0.4"/>
        <material name='floor_mat'      texture="floor_tex"  shininess="0.8" texrepeat="10 10" specular="0.7"  reflectance="0.5" />
        <material name='geom'           texture="texgeom"   texuniform="true" />
        <material name="bench_mat"      texture="metal1"   shininess="0.1" specular="0.5" reflectance="0.2"/>
        <material name="tablecube"      texture="wood" rgba=".8 .8 .8 1"/>
   	<material name="metal_box" reflectance="0.5" texrepeat="1 1" texture="metal1" texuniform="true"/>
    </asset>

    <!--Contacts-->
    <contact>
        <exclude body1="gripperpalm" body2="gripperfinger_1_link_1"/>
		<exclude body1="gripperpalm" body2="gripperfinger_2_link_1"/>
		<exclude body1="gripperpalm" body2="gripperfinger_middle_link_1"/>
        <exclude body1="box_link" body2="base_link"/>
		<exclude body1="base_link" body2="shoulder_link"/>
		<exclude body1="shoulder_link" body2="upper_arm_link"/>
        <exclude body1="upper_arm_link" body2="forearm_link"/>
		<exclude body1="forearm_link" body2="wrist_1_link"/>
		<exclude body1="wrist_1_link" body2="wrist_2_link"/>
        <exclude body1="wrist_2_link" body2="wrist_3_link"/>
        <exclude body1="wrist_3_link" body2="gripperpalm"/>
        <exclude body1="ee_link" body2="wrist_3_link"/>
        <exclude body1="ee_link" body2="gripperpalm"/>
    </contact>

    <!--<include file="plate-with-hole.xml">-->

    <!--MODEL DESCRIPTION-->
    <worldbody>
        <!--Lighting parameters-->
        <light name="light3" mode="targetbody" target="box_link" directional="true" pos="1 1 3" />
        <!--Camera parameters-->
        <camera name="main1" mode="trackcom" target="gripperpalm" pos="5 -2 2.7" axisangle="5 8 0 0.9"/>
        <!--Floor Property-->
        <geom name='floor' material="floor_mat" pos='0 0 0' size='2.5 2.5 0.1'  type='plane' />
	

           <!--     -->



		<!-- THIS IS OUR Cylinder -->
		<!-- quat="0.5 0.5 -0.5 0.5"   pos="-0.25 0.8 0.8675"    floor position = "+0.5 0.8 0" -->
	<body name="cylinder_play" pos="0.25 0.77  0.968">>
<!--        <body name="cylinder_play" pos="-0.25 0.8 0.8675">>-->
<!--            <geom name="cylinder1" type="cylinder" fromto="0.5 0 0.2  0.5 0 0" size="0.023"/>-->
            <geom name="cylinder1" type="box" size=".024 .024 .1"  euler="0 0 0"/>
            <joint type="free"/>
	    <inertial pos="0 0 0"  mass="0.2" diaginertia="1 1 1" />
        </body>

		<!-- THIS IS OUR TABLE -->
	<body name="OUR_TABLE" pos="0 0.8 0.435">
            <!--<geom size=".3 .2 .435" type="box" material="bench_mat"/>-->
            <geom size=".29 .19 .03" pos ="0 0 0.4" type="box" material="bench_mat"/>
            <geom size=".29 .19 .03" pos ="0 0 -0.2" type="box" material="bench_mat"/>
            <geom size=".04 .04 .435" pos =".26 .16 0" type="box" material="bench_mat"/>
            <geom size=".04 .04 .435" pos ="-.26 .16 0" type="box" material="bench_mat"/>
            <geom size=".04 .04 .435" pos =".26 -.16 0" type="box" material="bench_mat"/>
            <geom size=".04 .04 .435" pos ="-.26 -.16 0" type="box" material="bench_mat"/>
            <inertial pos="0 0 0" mass="1000" diaginertia="0 0 0" />
	</body>	



		<!-- THIS IS OUR BOX -->
             <!-- pos="-0.1 0.7 0.84171" -->
        <!-- <geom type="mesh" material="gripper_mat" mesh="BOX" /> 
     	<body name="box" pos="-0.1 0.7 0.8675">
             <joint type="free"/>
             <geom type="mesh" mesh="BOX" material="ur5_mat"/>
	     <inertial pos="0 0 0" quat="0.5 0.5 -0.5 0.5" mass="1" diaginertia="1 1 1" />
        </body>-->




	<body name="box" pos="-0.1 0.7 0.9">
		<body name="collision">
		
        <geom name="box_part_1" pos="0 0 -0.03" mesh="1" type="mesh" solimp="0.998 0.998 0.001" solref="0.001 1" density="6700" friction="0.95 0.3 0.1" 		    material="metal_box" group="1" condim="4" rgba="0 1 0 1"  />
		<geom name="box_part_2" pos="0 0 -0.03" mesh="2" type="mesh" solimp="0.998 0.998 0.001" solref="0.001 1" density="6700" friction="0.95 0.3 0.1" 			material="metal_box" group="1" condim="4" rgba="0 1 0 1"  />
        <geom name="box_part_3" pos="0 0 -0.03" mesh="3" type="mesh" solimp="0.998 0.998 0.001" solref="0.001 1" density="6700" friction="0.95 0.3 0.1" 			material="metal_box" group="1" condim="4" rgba="0 1 0 1"  />
		<geom name="box_part_4" pos="0 0 -0.03" mesh="4" type="mesh" solimp="0.998 0.998 0.001" solref="0.001 1" density="6700" friction="0.95 0.3 0.1" 			material="metal_box" group="1" condim="4" rgba="0 1 0 1"  />
		<geom name="box_part_5" pos="0 0 -0.03" mesh="5" type="mesh" solimp="0.998 0.998 0.001" solref="0.001 1" density="6700" friction="0.95 0.3 0.1" 			material="metal_box" group="1" condim="4" rgba="0 1 0 1"  />
		<geom name="box_part_6" pos="0 0 -0.03" mesh="6" type="mesh" solimp="0.998 0.998 0.001" solref="0.001 1" density="6700" friction="0.95 0.3 0.1" 			material="metal_box" group="1" condim="4" rgba="0 1 0 1"  />
		<geom name="box_part_7" pos="0 0 -0.03" mesh="7" type="mesh" solimp="0.998 0.998 0.001" solref="0.001 1" density="6700" friction="0.95 0.3 0.1" 			material="metal_box" group="1" condim="4" rgba="0 1 0 1"  />
		<geom name="box_part_8" pos="0 0 -0.03" mesh="8" type="mesh" solimp="0.998 0.998 0.001" solref="0.001 1" density="6700" friction="0.95 0.3 0.1" 			material="metal_box" group="1" condim="4" rgba="0 1 0 1"  />
		<geom name="box_part_9" pos="0 0 -0.03" mesh="9" type="mesh" solimp="0.998 0.998 0.001" solref="0.001 1" density="6700" friction="0.95 0.3 0.1" 			material="metal_box" group="1" condim="4" rgba="0 1 0 1"  />
		<geom name="box_part_10" pos="0 0 -0.03" mesh="10" type="mesh" solimp="0.998 0.998 0.001" solref="0.001 1" density="6700" friction="0.95 0.3 0.1" 		material="metal_box" group="1" condim="4" rgba="0 1 0 1"  />
        <geom name="box_part_11" pos="0 0 -0.03" mesh="11" type="mesh" solimp="0.998 0.998 0.001" solref="0.001 1" density="6700" friction="0.95 0.3 0.1" 		material="metal_box" group="1" condim="4" rgba="0 1 0 1"  />
		<geom name="box_part_12" pos="0 0 -0.03" mesh="12" type="mesh" solimp="0.998 0.998 0.001" solref="0.001 1" density="6700" friction="0.95 0.3 0.1" 		material="metal_box" group="1" condim="4" rgba="0 1 0 1"  />

        <site name="middle_cube" pos="0.07 0.07 -0.03" size="0.002 0.002 0.002" />
		<site name="middle_cylinder" pos="0.24 0.07 -0.03" size="0.002 0.002 0.002" />
		<site name="middle_triangle" pos="0.148 0.07 -0.03" size="0.002 0.002 0.002" />
				
		<site name="hole_up_1" pos="0 0 0.058" size="0.002 0.002 0.002" />
		<site name="hole_up_2" pos="0 0.15 0.058" size="0.002 0.002 0.002" />
		<site name="hole_up_3" pos="0.3 0 0.058" size="0.002 0.002 0.002" />
		<site name="hole_up_4" pos="0.3 0.15 0.058" size="0.002 0.002 0.002" />
		
		<site name="hole_down_1" pos="0 0 -0.03" size="0.002 0.002 0.002" />
		<site name="hole_down_2" pos="0 0.15 -0.03" size="0.002 0.002 0.002" />
		<site name="hole_down_3" pos="0.3 0 -0.03" size="0.002 0.002 0.002" />
		<site name="hole_down_4" pos="0.3 0.15 -0.03" size="0.002 0.002 0.002" />

		<body name="asdas" pos="0.077 0.077 -0.03">
			<geom density="3000" friction="1.0 0.005 0.0001" group="1" name="cube2"  rgba="1 0 0 1" size="0.002 0.002 0.002" type="box" />
		</body>
		<body name="asdasasd" pos="0.264 0.077 -0.03">
			<geom density="3000" friction="1.0 0.005 0.0001" group="1" name="cube23"  rgba="1 0 0 1" size="0.002 0.002 0.002" type="box"/>
	
		</body>
		<body name="asdaasds" pos="0.24 0.07 -0.03">
			<geom density="3000" friction="1.0 0.005 0.0001" group="1" name="cube3"  rgba="1 0 0 1" size="0.002 0.002 0.002" type="box" />
		</body>
		</body>

      <body name="visual">
        <!--  <geom pos="0 0 0" size="0.1 0.25 0.02" type="box" rgba="1 0 0 1"/>
        <geom pos="0.3 0 0" size="0.1 0.25 0.02" type="box" rgba="1 0 0 1"/>
        <geom pos="0.15 0.15 0" size="0.05 0.1 0.02" type="box" rgba="1 0 0 1"/>
        <geom pos="0.15 -0.15 0" size="0.05 0.1 0.02" type="box" rgba="1 0 0 1"/>-->
      </body>

      <site rgba="0 0 0 0" size="0.005" pos="0 0 -0.02" name="bottom_site"/>
      <site rgba="0 0 0 0" size="0.005" pos="0 0 0.02" name="top_site"/>
      <site rgba="0 0 0 0" size="0.005" pos="0.25 0.25 0.1" name="horizontal_radius_site"/>
    </body>
		


	


	
        <!--Robot UR5-->
        <body name="box_link" pos="0 0 0.435">
            <!--<geom size=".3 .2 .435" type="box" material="bench_mat"/>-->
            <geom size=".29 .19 .03" pos ="0 0 0.4" type="box" material="bench_mat"/>
            <geom size=".29 .19 .03" pos ="0 0 -0.2" type="box" material="bench_mat"/>
            <geom size=".04 .04 .435" pos =".26 .16 0" type="box" material="bench_mat"/>
            <geom size=".04 .04 .435" pos ="-.26 .16 0" type="box" material="bench_mat"/>
            <geom size=".04 .04 .435" pos =".26 -.16 0" type="box" material="bench_mat"/>
            <geom size=".04 .04 .435" pos ="-.26 -.16 0" type="box" material="bench_mat"/>
            <inertial pos="0 0 0" mass="1000" diaginertia="0 0 0" />
            <body name="base_link" pos="0 0 0.435">
                <inertial pos="0 0 0" quat="0.5 0.5 -0.5 0.5" mass="4" diaginertia="0.0072 0.00443333 0.00443333" />
                <geom type="mesh"  mesh="base" material="ur5_mat"/>
                <body name="shoulder_link" pos="0 0 0.089159">
                    <inertial pos="0 0 0" mass="3.7" diaginertia="0.0102675 0.0102675 0.00666" />
                    <joint name="shoulder_pan_joint" class="UR5" pos="0 0 0" axis="0 0 1" limited="true" range="-3.14159 3.14159" />
                    <geom type="mesh"  mesh="shoulder" material="ur5_mat"/>
                    <body name="upper_arm_link" pos="0 0.13585 0" quat="0.707107 0 0.707107 0">
                        <inertial pos="0 0 0.28" mass="8.393" diaginertia="0.226891 0.226891 0.0151074" />
                        <joint name="shoulder_lift_joint" class="UR5" pos="0 0 0" axis="0 1 0" limited="true" range="-3.14159 0" /> <!--Range= -3.14159 3.14159-->
                        <geom type="mesh"  mesh="upperarm" material="ur5_mat"/>
                        <body name="forearm_link" pos="0 -0.1197 0.425">
                            <inertial pos="0 0 0.25" mass="2.275" diaginertia="0.0494433 0.0494433 0.004095" />
                            <joint name="elbow_joint" class="UR5" pos="0 0 0" axis="0 1 0" limited="true" range="-3.14159 3.14159" />
                            <geom type="mesh"  mesh="forearm" material="ur5_mat"/>
                            <body name="wrist_1_link" pos="0 0 0.39225" quat="0.707107 0 0.707107 0">
                                <inertial pos="0 0 0" quat="0.5 0.5 -0.5 0.5" mass="1.219" diaginertia="0.21942 0.111173 0.111173" />
                                <joint name="wrist_1_joint" class="UR5e" pos="0 0 0" axis="0 1 0" limited="true" range="-3.14159 3.14159" />
                                <geom type="mesh"  mesh="wrist1" material="ur5_mat"/>
                                <body name="wrist_2_link" pos="0 0.093 0">
                                    <inertial pos="0 0 0" quat="0.5 0.5 -0.5 0.5" mass="1.219" diaginertia="0.21942 0.111173 0.111173" />
                                    <joint name="wrist_2_joint" class="UR5e" pos="0 0 0" axis="0 0 1" limited="true" range="-3.14159 3.14159" />
                                    <geom type="mesh"  mesh="wrist2" material="ur5_mat"/>
                                    <body name="wrist_3_link" pos="0 0 0.09465">
                                        <site name="wrist_3_link" pos="0 0.05 0" size="0.045 0.045.0065" />
                                        <inertial pos="0 0 0" quat="0.5 0.5 -0.5 0.5" mass="0.1879" diaginertia="0.033822 0.0171365 0.0171365" />
                                        <joint name="wrist_3_joint" class="UR5e" pos="0 0 0" axis="0 1 0" limited="true" range="-3.14159 3.14159" />
                                        <geom name="wrist_3_link" type="mesh"  mesh="wrist3" material="ur5_mat" rgba="1 0 0 1"/>
                                        <body name="ee_link" pos="0 0.0823 0" quat="0.707107 0 0 0.707107">
                                            <inertial pos="-0.01 0 0" mass="0.001" diaginertia="1.66667e-08 1.66667e-08 1.66667e-08" />
                                            <geom size="0.005 0.005 0.005" pos="-0.01 0 0" type="box" />
                                        </body>
                                        <!--GRIPPER-->
                                        <body name="tool0" pos="0 0.0823 0" quat="0.707107 -0.707107 0 0">
                                            <inertial pos="0 0.0823 0" quat="0.707107 -0.707107 0 0" mass="0" diaginertia="0 0 0" />
                                            <body name="gripperpalm" pos="0 0 0.0423" quat="0.707107 0.707107 0 0">
                                                <site name="gripperpalm" pos="0 0.05 0" size="0.045 0.0065 0.045"/>
                                                <inertial pos="0 0 0" mass="1.3" diaginertia="0.0035 0.0035 0.0035" />
                                                <geom name="gripperpalm" type="mesh"  mesh="gripperpalm" material="gripper_mat" />
						
                                                <!--FINGERS-->
                                                <body name="gripperfinger_1_link_0" pos="-0.0455 0.0214 0.036" quat="-2.59838e-06 0.706825 0.707388 2.59631e-06">
                                                    <inertial pos="-0.01 0 0" quat="0.5 0.5 0.5 0.5" mass="0.1" diaginertia="2.5e-05 2.5e-05 1.8e-05" />
                                                    <joint name="gripperpalm_finger_1_joint" class="GRIPPER" pos="0 0 0" axis="0 1 0" limited="true" range="-0.2967 0.2967" />
                                                    <geom type="mesh" material="gripper_mat" mesh="link_0" />
                                                    <body name="gripperfinger_1_link_1" pos="0 0 0" quat="0.501642 0 0 -0.865075">
                                                        <site name="gripperfinger_1_polp_1" pos="-0.005 0.035 0" size=".006 .014 .014"/>
                                                        <inertial pos="0.00053 0.03218 0" quat="0.00544471 0.00542787 0.707078 0.707093" mass="0.047" diaginertia="6.43594e-05 6.06192e-05 4.97928e-06" />
                                                        <joint name="gripperfinger_1_joint_1" class="GRIPPER" pos="0 0 0" axis="0 0 1" limited="true" range="0 1.2217" />
                                                        <geom pos="0 0.05717 0" quat="0.707105 0 0 0.707108" type="mesh" material="gripper_mat" mesh="link_1" />
                                                        <body name="gripperfinger_1_link_2" pos="0 0.05715 0">
                                                            <site name="gripperfinger_1_polp_2" pos="-0.006 0.02 0" size=".006 .014 .014"/>
                                                            <inertial pos="0.00048 0.02167 0.00018" quat="0.00523005 0.00665272 0.709882 0.70427" mass="0.03284" diaginertia="2.24866e-05 1.98645e-05 3.47368e-06" />
                                                            <joint name="gripperfinger_1_joint_2" class="GRIPPER" pos="0 0 0" axis="0 0 1" limited="true" range="0 1.5708" />
                                                            <geom pos="0 0.0381 0.0075" quat="0.707105 0 0 0.707108" type="mesh" material="gripper_mat" mesh="link_2" />
                                                            <body name="gripperfinger_1_link_3" pos="0 0.039 0" quat="0.501642 0 0 0.865075">
                                                                <site name="gripperfinger_1_polp_3" pos="0.025 0.006 0" size=".014 .006 .014"/>
                                                                <inertial pos="0.01626 0.00049 0.0002" quat="0.520969 0.517877 0.481643 0.477927" mass="0.03354" diaginertia="1.43512e-05 1.26412e-05 2.98016e-06" />
                                                                <joint name="gripperfinger_1_joint_3" class="GRIPPER" pos="0 0 0" axis="0 0 1" limited="true" range="-0.6632 1.0471" />
                                                                <geom type="mesh" material="gripper_mat" mesh="link_3" />
								<!--Add cylinder here-->
                                                            </body>
                                                        </body>
                                                    </body>
                                                </body>
                                                <body name="gripperfinger_2_link_0" pos="-0.0455 0.0214 -0.036" quat="-2.59838e-06 0.706825 0.707388 2.59631e-06">
                                                    <inertial pos="-0.01 0 0" quat="0.5 0.5 0.5 0.5" mass="0.1" diaginertia="2.5e-05 2.5e-05 1.8e-05" />
                                                    <joint name="gripperpalm_finger_2_joint" class="GRIPPER" pos="0 0 0" axis="0 1 0" limited="true" range="-0.2967 0.2967" />
                                                    <geom type="mesh" material="gripper_mat" mesh="link_0" />
                                                    <body name="gripperfinger_2_link_1" pos="0 0 0" quat="0.501642 0 0 -0.865075">
                                                        <site name="gripperfinger_2_polp_1" pos="-0.005 0.035 0" size=".006 .014 .014"/>
                                                        <inertial pos="0.00053 0.03218 0" quat="0.00544471 0.00542787 0.707078 0.707093" mass="0.047" diaginertia="6.43594e-05 6.06192e-05 4.97928e-06" />
                                                        <joint name="gripperfinger_2_joint_1" class="GRIPPER" pos="0 0 0" axis="0 0 1" limited="true" range="0 1.2217" />
                                                        <geom pos="0 0.05717 0" quat="0.707105 0 0 0.707108" type="mesh" material="gripper_mat" mesh="link_1" />
                                                        <body name="gripperfinger_2_link_2" pos="0 0.05715 0">
                                                            <site name="gripperfinger_2_polp_2" pos="-0.006 0.02 0" size=".006 .014 .014"/>
                                                            <inertial pos="0.00048 0.02167 0.00018" quat="0.00523005 0.00665272 0.709882 0.70427" mass="0.03284" diaginertia="2.24866e-05 1.98645e-05 3.47368e-06" />
                                                            <joint name="gripperfinger_2_joint_2" class="GRIPPER" pos="0 0 0" axis="0 0 1" limited="true" range="0 1.5708" />
                                                            <geom pos="0 0.0381 0.0075" quat="0.707105 0 0 0.707108" type="mesh" material="gripper_mat" mesh="link_2" />
                                                            <body name="gripperfinger_2_link_3" pos="0 0.039 0" quat="0.501642 0 0 0.865075">
                                                                <site name="gripperfinger_2_polp_3" pos="0.025 0.006 0" size=".014 .006 .014"/>
                                                                <inertial pos="0.01626 0.00049 0.0002" quat="0.520969 0.517877 0.481643 0.477927" mass="0.03354" diaginertia="1.43512e-05 1.26412e-05 2.98016e-06" />
                                                                <joint name="gripperfinger_2_joint_3" class="GRIPPER" pos="0 0 0" axis="0 0 1" limited="true" range="-0.6632 1.0471" />
                                                                <geom type="mesh" material="gripper_mat" mesh="link_3" />
                                                            </body>
                                                        </body>
                                                    </body>
                                                </body>
                                                <body name="gripperfinger_middle_link_0" pos="0.0455 0.0214 0" quat="0.707388 0 0 0.706825">
                                                    <inertial pos="-0.01 0 0" quat="0.5 0.5 0.5 0.5" mass="0.1" diaginertia="2.5e-05 2.5e-05 1.8e-05" />
                                                    <joint name="gripperpalm_finger_middle_joint" class="GRIPPER" pos="0 0 0" axis="0 1 0"  limited="true" range="-1e-3 1e-3"/> <!--RANGE CAMBIATO (In realtà aggiunto, non c'era ??) A MANO DA ME PER LA STABILITA DEL POLLICE-->
                                                    <geom type="mesh" material="gripper_mat" mesh="link_0" />
                                                    <body name="gripperfinger_middle_link_1" pos="0 0 0" quat="0.501642 0 0 -0.865075">
                                                        <site name="gripperfinger_middle_polp_1" pos="-0.005 0.035 0" size=".006 .014 .014"/>
                                                        <inertial pos="0.00053 0.03218 0" quat="0.00544471 0.00542787 0.707078 0.707093" mass="0.047" diaginertia="6.43594e-05 6.06192e-05 4.97928e-06" />
                                                        <joint name="gripperfinger_middle_joint_1" class="GRIPPER" pos="0 0 0" axis="0 0 1" limited="true" range="0 1.2217" />
                                                        <geom pos="0 0.05717 0" quat="0.707105 0 0 0.707108" type="mesh" material="gripper_mat" mesh="link_1" />
                                                        <body name="gripperfinger_middle_link_2" pos="0 0.05715 0">
                                                            <site name="gripperfinger_middle_polp_2" pos="-0.006 0.02 0" size=".006 .014 .014"/>
                                                            <inertial pos="0.00048 0.02167 0.00018" quat="0.00523005 0.00665272 0.709882 0.70427" mass="0.03284" diaginertia="2.24866e-05 1.98645e-05 3.47368e-06" />
                                                            <joint name="gripperfinger_middle_joint_2" class="GRIPPER" pos="0 0 0" axis="0 0 1" limited="true" range="0 1.5708" />
                                                            <geom pos="0 0.0381 0.0075" quat="0.707105 0 0 0.707108" type="mesh" material="gripper_mat" mesh="link_2" />
                                                            <body name="gripperfinger_middle_link_3" pos="0 0.039 0" quat="0.501642 0 0 0.865075">
                                                                <site name="gripperfinger_middle_polp_3" pos="0.025 0.006 0" size=".014 .006 .014"/>
                                                                <inertial pos="0.01626 0.00049 0.0002" quat="0.520969 0.517877 0.481643 0.477927" mass="0.03354" diaginertia="1.43512e-05 1.26412e-05 2.98016e-06" />
                                                                <joint name="gripperfinger_middle_joint_3" class="GRIPPER" pos="0 0 0" axis="0 0 1" limited="true" range="-0.6632 1.0471" />
                                                                <geom type="mesh" material="gripper_mat" mesh="link_3" />
                                                            </body>
                                                        </body>
                                                    </body>
                                                </body>
                                            </body>
                                        </body>
                                    </body>
                                </body>
                            </body>
                        </body>
                    </body>
                </body>
                <body name="base" pos="0 0 0" quat="1.7949e-09 0 0 -1">
                    <inertial pos="0 0 0" quat="1.7949e-09 0 0 -1" mass="0" diaginertia="0 0 0" />
                </body>
            </body>
        </body>

    </worldbody>


    <tendon>
		<!--Middlefinger tendons-->
		<fixed name="middle12_cpl" range="0 1">
			<joint joint="gripperfinger_middle_joint_1"  coef="1"/>
			<joint joint="gripperfinger_middle_joint_2"  coef="-1.5"/>
		</fixed>
		<fixed name="middle23_cpl" range="0 1">
			<joint joint="gripperfinger_middle_joint_2"  coef="1"/>
			<joint joint="gripperfinger_middle_joint_3"  coef="-3.5"/>
		</fixed>

		<!--finger2 tendons-->
        <fixed name="finger2_12_cpl" range="0 1">
			<joint joint="gripperfinger_2_joint_1"  coef="1"/>
			<joint joint="gripperfinger_2_joint_2"  coef="-1.5"/>
		</fixed>
		<fixed name="finger2_23_cpl" range="0 1">
			<joint joint="gripperfinger_2_joint_2"  coef="1"/>
			<joint joint="gripperfinger_2_joint_3"  coef="-3.5"/>
		</fixed>

		<!--Finger1 tendons-->
        <fixed name="finger1_12_cpl" range="0 1">
			<joint joint="gripperfinger_1_joint_1"  coef="1"/>
			<joint joint="gripperfinger_1_joint_2"  coef="-1.5"/>
		</fixed>
		<fixed name="finger1_23_cpl" range="0 1">
			<joint joint="gripperfinger_1_joint_2"  coef="1"/>
			<joint joint="gripperfinger_1_joint_3"  coef="-3.5"/>
		</fixed>
	</tendon>

    <equality>
		<!-- GRIPPER Couplings -->
		<tendon name="middle12_cpl" 	tendon1="middle12_cpl"/>
		<tendon name="middle23_cpl" 	tendon1="middle23_cpl"/>

        <tendon name="finger2_12_cpl" 	tendon1="finger2_12_cpl"/>
		<tendon name="finger2_23_cpl" 	tendon1="finger2_23_cpl"/>

        <tendon name="finger1_12_cpl" 	tendon1="finger1_12_cpl"/>
		<tendon name="finger1_23_cpl" 	tendon1="finger1_23_cpl"/>

		<!-- SCISSOR Coupling -->
		<joint name="finger_12_scissor" joint1="gripperpalm_finger_2_joint" joint2="gripperpalm_finger_1_joint" polycoef="0 -1 0 0 0"/>
	<weld name="OUR_TABLE"    body1="OUR_TABLE"   body2="box"  />     
	</equality>


    <!--ACTUATORS-->
    <actuator>
        <!--UR5-->
        <!--<position name='shoulder_pan' ctrllimited="true" ctrlrange="-3.14159 3.14159" joint='shoulder_pan_joint' kp="500"/>-->
        <!--<position name='shoulder_lift' ctrllimited="true" ctrlrange="-3.14159 3.14159" joint='shoulder_lift_joint' kp="500"/>-->
        <!--<position name='forearm' ctrllimited="true" ctrlrange="-3.14159 3.14159" joint='elbow_joint' kp="500"/>-->
        <!--<position name='wrist_1' ctrllimited="true" ctrlrange="-3.14159 3.14159" joint='wrist_1_joint' kp="100"/>-->
        <!--<position name='wrist_2' ctrllimited="true" ctrlrange="-3.14159 3.14159" joint='wrist_2_joint' kp="100"/>-->
        <!--<position name='wrist_3' ctrllimited="true" ctrlrange="-3.14159 3.14159" joint='wrist_3_joint' kp="100"/>-->

        <motor name='shoulder_pan_T' ctrllimited="true" ctrlrange="-2 2" joint='shoulder_pan_joint' gear="101"/> <!--range -150 150-->
        <motor name='shoulder_lift_T' ctrllimited="true" ctrlrange="-2 2" joint='shoulder_lift_joint' gear="101"/>
        <motor name='forearm_T' ctrllimited="true" ctrlrange="-2 2" joint='elbow_joint' gear="101" />
        <motor name='wrist_1_T' ctrllimited="true" ctrlrange="-1 1" joint='wrist_1_joint' gear="101"/>  <!--range -28 28-->
        <motor name='wrist_2_T' ctrllimited="true" ctrlrange="-1 1" joint='wrist_2_joint' gear="101"/>
        <motor name='wrist_3_T' ctrllimited="true" ctrlrange="-1 1" joint='wrist_3_joint' gear="101"/>

        <!--<velocity name='shoulder_pan_v' class="UR5" joint='shoulder_pan_joint' kv="10"/>-->
        <!--<velocity name='shoulder_lift_v' class="UR5" joint='shoulder_lift_joint' />-->
        <!--<velocity name='forearm_v' class="UR5" joint='elbow_joint' />-->
        <!--<velocity name='wrist_1_v' class="UR5" joint='wrist_1_joint' />-->
        <!--<velocity name='wrist_2_v' class="UR5" joint='wrist_2_joint'/>-->
        <!--<velocity name='wrist_3_v' class="UR5" joint='wrist_3_joint'/>-->

        <!--Gripper-->
        <!--<position name='finger_1' ctrllimited="true" kp="20" joint='gripperfinger_1_joint_1' ctrlrange='0 1.2217'/>-->
        <!--<position name='finger_2' ctrllimited="true" kp="20" joint='gripperfinger_2_joint_1' ctrlrange='0 1.2217'/>-->
        <!--<position name='middle_finger'  ctrllimited="true" kp="20" joint='gripperfinger_middle_joint_1' ctrlrange='0 1.2217'/>-->
        <!--<position name='finger_scissor' ctrllimited="true" kp="20" joint='gripperpalm_finger_1_joint' ctrlrange="-0.2967 0.2967"/>-->

        <motor name='finger_1_T' ctrllimited="true" joint='gripperfinger_1_joint_1' ctrlrange='-0.1 .8' gear="20"/>
        <motor name='finger_2_T' ctrllimited="true" joint='gripperfinger_2_joint_1' ctrlrange='-0.1 .8' gear="20"/>
        <motor name='middle_finger_T'  ctrllimited="true" joint='gripperfinger_middle_joint_1' ctrlrange='-0.1 .8' gear="20"/>
        <motor name='finger_scissor_T' ctrllimited="true" joint='gripperpalm_finger_1_joint' ctrlrange="-0.8 0.8" gear="15"/>
    </actuator>

    <sensor>
        <touch name="gripperpalm_norm" 		site="gripperpalm"/>
<!--        <touch name="wrist_3_link_frc" 		site="wrist_3_link"/>-->

<!--        <force name="finger1_p1_f"	site="gripperfinger_1_polp_1"/>-->
<!--    	<force name="finger1_p2_f" 	site="gripperfinger_1_polp_2"/>-->
<!--        <force name="finger1_p3_f" 	site="gripperfinger_1_polp_3"/>-->

<!--        <force name="finger2_p1_f" 	site="gripperfinger_2_polp_1"/>-->
<!--        <force name="finger2_p2_f" 	site="gripperfinger_2_polp_2"/>-->
<!--        <force name="finger2_p3_f" 	site="gripperfinger_2_polp_3"/>-->

<!--        <force name="finger3_p1_f" 	site="gripperfinger_middle_polp_1"/>-->
<!--        <force name="finger3_p2_f" 	site="gripperfinger_middle_polp_2"/>-->
<!--        <force name="finger3_p3_f" 	site="gripperfinger_middle_polp_3"/>-->

	    <force name='end' site='gripperpalm'/>
        <force name="wrist_3_link_f" 		site="wrist_3_link"/>
        <torque name="wrist_3_link_t" 		site="wrist_3_link"/>
    </sensor>
</mujoco>
